Workbook

Sheet 【表1-使用说明】必读！
A1: 表格使用说明 | B1: 知乎/焚躯以火；公众号/云开天明
B2: 修改日期：2025/7/9
A3: 打开工作表2“太阳位置计算器”，如右图。
A4: 工作表分为五个区域：基本设置区、参数设定区、结果输出区、单时刻太阳位置计算、当日时间序列。
A5: 填写基本设置和参数设定的六个参数，填完后，表格会自动计算太阳赤纬角、日出日落时间、月龄月相、各个时刻的太阳高度角、太阳方位角等数据。
A7: 名词解释：
A8: 标准时间时区：如果你在中国，使用UTC+8(北京时间)。
A9: 时间基准：两个选项分别为平太阳时/真太阳时。平太阳时是你手机、手表显示的标准时间；真太阳时反映了太阳的真实位置，默认正午时刻为当地时间12时整。我们日常使用的是平太阳时，所以默认设定为平太阳时。
A10: 太阳赤纬角：太阳入射光与地球赤道之间的角度
A11: 太阳方位角：太阳相对于正北方向的顺时针转过的角度，正北=0°，正东=90°，正南=180°,正西=270°.
A12: 太阳高度角：太阳入射光和地面的夹角。
A13: 点钟方向：钟表盘上12点指向正北方时，太阳所处的方位在钟表上对应的数字位置。可用来确定方位。将钟表盘上该数字对准太阳，此时表盘上的12点是正北，6点是正南。
A14: 月龄：从新月时刻开始，到达观测时刻所经历的天数。本表格中月龄的计算选用的是当地时间正午12:00.
A15: 月相：在地球上看月球，月球被太阳照明的部分，呈周期性的变化，一个周期为29.53天。本表格将月相分为9种：新月、娥眉月、上弦月、盈凸月、满月、亏凸月、下弦月、残月、晦月。
... A24: 点击这里跳转网页

Sheet 【表2】太阳位置计算器
A1: 基本设置 | F1: 标准 时间 | G1: 太阳 方位角 | H1: 太阳 高度角 | I1: 点钟 方向
A3: 标准时间时区 | C3: UTC+8(北京时间) | F3: 0:00 | G3: =IF(F3="", "", VLOOKUP(F3,【表3】处理过程壹!$E$8:$J$55, 5, FALSE)) -> 355.05172 | H3: =IF(F3="", "", VLOOKUP(F3,【表3】处理过程壹!$E$8:$J$55, 6, FALSE)) -> -37.159908 | I3: =IF(F3="", "", G3/30) -> 11.835057
A4: 时间基准 | C4: 平太阳时(推荐) | F4: =IF(F3="", "", IF((F3+【表3】处理过程壹!$E$5/24) >= 1, "", TEXT(F3+【表3】处理过程壹!$E$5/24,"h:mm"))) -> 0:30 | G4: =IF(F4="", "", VLOOKUP(F4,【表3】处理过程壹!$E$8:$J$55, 5, FALSE)) -> 3.7467785 | H4: =IF(F4="", "", VLOOKUP(F4,【表3】处理过程壹!$E$8:$J$55, 6, FALSE)) -> -37.228064 | I4: =IF(F4="", "", G4/30) -> 0.12489262
A5: 时间序列间隔 | C5: 30分钟 | F5: =IF(F4="", "", IF((F4+【表3】处理过程壹!$E$5/24) >= 1, "", TEXT(F4+【表3】处理过程壹!$E$5/24,"h:mm"))) -> 1:00 | G5: =IF(F5="", "", VLOOKUP(F5,【表3】处理过程壹!$E$8:$J$55, 5, FALSE)) -> 12.319737 | H5: =IF(F5="", "", VLOOKUP(F5,【表3】处理过程壹!$E$8:$J$55, 6, FALSE)) -> -36.319703 | I5: =IF(F5="", "", G5/30) -> 0.41065789
F6: =IF(F5="", "", IF((F5+【表3】处理过程壹!$E$5/24) >= 1, "", TEXT(F5+【表3】处理过程壹!$E$5/24,"h:mm"))) -> 1:30 | G6: =IF(F6="", "", VLOOKUP(F6,【表3】处理过程壹!$E$8:$J$55, 5, FALSE)) -> 20.513595 | H6: =IF(F6="", "", VLOOKUP(F6,【表3】处理过程壹!$E$8:$J$55, 6, FALSE)) -> -34.483036 | I6: =IF(F6="", "", G6/30) -> 0.68378651
A7: 参数设定 | F7: =IF(F6="", "", IF((F6+【表3】处理过程壹!$E$5/24) >= 1, "", TEXT(F6+【表3】处理过程壹!$E$5/24,"h:mm"))) -> 2:00 | G7: =IF(F7="", "", VLOOKUP(F7,【表3】处理过程壹!$E$8:$J$55, 5, FALSE)) -> 28.143963 | H7: =IF(F7="", "", VLOOKUP(F7,【表3】处理过程壹!$E$8:$J$55, 6, FALSE)) -> -31.806485 | I7: =IF(F7="", "", G7/30) -> 0.93813209
F8: =IF(F7="", "", IF((F7+【表3】处理过程壹!$E$5/24) >= 1, "", TEXT(F7+【表3】处理过程壹!$E$5/24,"h:mm"))) -> 2:30 | G8: =IF(F8="", "", VLOOKUP(F8,【表3】处理过程壹!$E$8:$J$55, 5, FALSE)) -> 35.115624 | H8: =IF(F8="", "", VLOOKUP(F8,【表3】处理过程壹!$E$8:$J$55, 6, FALSE)) -> -28.4003 | I8: =IF(F8="", "", G8/30) -> 1.1705208
A9: 日期 | C9: 45846 | F9: =IF(F8="", "", IF((F8+【表3】处理过程壹!$E$5/24) >= 1, "", TEXT(F8+【表3】处理过程壹!$E$5/24,"h:mm"))) -> 3:00 | G9: =IF(F9="", "", VLOOKUP(F9,【表3】处理过程壹!$E$8:$J$55, 5, FALSE)) -> 41.41132 | H9: =IF(F9="", "", VLOOKUP(F9,【表3】处理过程壹!$E$8:$J$55, 6, FALSE)) -> -24.379123 | I9: =IF(F9="", "", G9/30) -> 1.3803773
A10: 观测点经度 | C10: 116.9 | F10: =IF(F9="", "", IF((F9+【表3】处理过程壹!$E$5/24) >= 1, "", TEXT(F9+【表3】处理过程壹!$E$5/24,"h:mm"))) -> 3:30 | G10: =IF(F10="", "", VLOOKUP(F10,【表3】处理过程壹!$E$8:$J$55, 5, FALSE)) -> 47.067443 | H10: =IF(F10="", "", VLOOKUP(F10,【表3】处理过程壹!$E$8:$J$55, 6, FALSE)) -> -19.849991 | I10: =IF(F10="", "", G10/30) -> 1.5689148
A11: 观测点纬度 | C11: 30.1 | F11: =IF(F10="", "", IF((F10+【表3】处理过程壹!$E$5/24) >= 1, "", TEXT(F10+【表3】处理过程壹!$E$5/24,"h:mm"))) -> 4:00 | G11: =IF(F11="", "", VLOOKUP(F11,【表3】处理过程壹!$E$8:$J$55, 5, FALSE)) -> 52.149901 | H11: =IF(F11="", "", VLOOKUP(F11,【表3】处理过程壹!$E$8:$J$55, 6, FALSE)) -> -14.906356 | I11: =IF(F11="", "", G11/30) -> 1.73833
F12: =IF(F11="", "", IF((F11+【表3】处理过程壹!$E$5/24) >= 1, "", TEXT(F11+【表3】处理过程壹!$E$5/24,"h:mm"))) -> 4:30 | G12: =IF(F12="", "", VLOOKUP(F12,【表3】处理过程壹!$E$8:$J$55, 5, FALSE)) -> 56.73637 | H12: =IF(F12="", "", VLOOKUP(F12,【表3】处理过程壹!$E$8:$J$55, 6, FALSE)) -> -9.6265057 | I12: =IF(F12="", "", G12/30) -> 1.8912123
A13: 结果输出 | F13: =IF(F12="", "", IF((F12+【表3】处理过程壹!$E$5/24) >= 1, "", TEXT(F12+【表3】处理过程壹!$E$5/24,"h:mm"))) -> 5:00 | G13: =IF(F13="", "", VLOOKUP(F13,【表3】处理过程壹!$E$8:$J$55, 5, FALSE)) -> 60.905655 | H13: =IF(F13="", "", VLOOKUP(F13,【表3】处理过程壹!$E$8:$J$55, 6, FALSE)) -> -4.0745008 | I13: =IF(F13="", "", G13/30) -> 2.0301885
F14: =IF(F13="", "", IF((F13+【表3】处理过程壹!$E$5/24) >= 1, "", TEXT(F13+【表3】处理过程壹!$E$5/24,"h:mm"))) -> 5:30 | G14: =IF(F14="", "", VLOOKUP(F14,【表3】处理过程壹!$E$8:$J$55, 5, FALSE)) -> 64.732548 | H14: =IF(F14="", "", VLOOKUP(F14,【表3】处理过程壹!$E$8:$J$55, 6, FALSE)) -> 1.6978359 | I14: =IF(F14="", "", G14/30) -> 2.1577516
A15: 太阳赤纬角 | C15: =【表3】处理过程壹!$K$5 -> 22.580541 | F15: =IF(F14="", "", IF((F14+【表3】处理过程壹!$E$5/24) >= 1, "", TEXT(F14+【表3】处理过程壹!$E$5/24,"h:mm"))) -> 6:00 | G15: =IF(F15="", "", VLOOKUP(F15,【表3】处理过程壹!$E$8:$J$55, 5, FALSE)) -> 68.286292 | H15: =IF(F15="", "", VLOOKUP(F15,【表3】处理过程壹!$E$8:$J$55, 6, FALSE)) -> 7.6486797 | I15: =IF(F15="", "", G15/30) -> 2.2762097
A16: 日出时间 | B16: =【表3】处理过程壹!P8 -> 5:21:17 | C16: 日出方位 | D16: =【表3】处理过程壹!Q8 -> 63.651375 | F16: =IF(F15="", "", IF((F15+【表3】处理过程壹!$E$5/24) >= 1, "", TEXT(F15+【表3】处理过程壹!$E$5/24,"h:mm"))) -> 6:30 | G16: =IF(F16="", "", VLOOKUP(F16,【表3】处理过程壹!$E$8:$J$55, 5, FALSE)) -> 71.631258 | H16: =IF(F16="", "", VLOOKUP(F16,【表3】处理过程壹!$E$8:$J$55, 6, FALSE)) -> 13.744114 | I16: =IF(F16="", "", G16/30) -> 2.3877086
A17: 日中时间 | B17: =【表3】处理过程壹!P9 -> 12:17:05 | C17: 中天高度 | D17: =【表3】处理过程壹!Q9 -> 82.480541 | F17: =IF(F16="", "", IF((F16+【表3】处理过程壹!$E$5/24) >= 1, "", TEXT(F16+【表3】处理过程壹!$E$5/24,"h:mm"))) -> 7:00 | G17: =IF(F17="", "", VLOOKUP(F17,【表3】处理过程壹!$E$8:$J$55, 5, FALSE)) -> 74.82908 | H17: =IF(F17="", "", VLOOKUP(F17,【表3】处理过程壹!$E$8:$J$55, 6, FALSE)) -> 19.956309 | I17: =IF(F17="", "", G17/30) -> 2.4943027
A18: 日落时间 | B18: =【表3】处理过程壹!P10 -> 19:12:53 | C18: 日落方位 | D18: =【表3】处理过程壹!Q10 -> 296.34863 | F18: =IF(F17="", "", IF((F17+【表3】处理过程壹!$E$5/24) >= 1, "", TEXT(F17+【表3】处理过程壹!$E$5/24,"h:mm"))) -> 7:30 | G18: =IF(F18="", "", VLOOKUP(F18,【表3】处理过程壹!$E$8:$J$55, 5, FALSE)) -> 77.942098 | H18: =IF(F18="", "", VLOOKUP(F18,【表3】处理过程壹!$E$8:$J$55, 6, FALSE)) -> 26.261967 | I18: =IF(F18="", "", G18/30) -> 2.5980699
A19: 昼长 | C19: =【表3】处理过程壹!P11 -> 13时51分 | F19: =IF(F18="", "", IF((F18+【表3】处理过程壹!$E$5/24) >= 1, "", TEXT(F18+【表3】处理过程壹!$E$5/24,"h:mm"))) -> 8:00 | G19: =IF(F19="", "", VLOOKUP(F19,【表3】处理过程壹!$E$8:$J$55, 5, FALSE)) -> 81.038565 | H19: =IF(F19="", "", VLOOKUP(F19,【表3】处理过程壹!$E$8:$J$55, 6, FALSE)) -> 32.640938 | I19: =IF(F19="", "", G19/30) -> 2.7012855
A20: 正午月龄 | B20: =【表4】处理过程贰!F6 -> 12.439428 | C20: 月相 | D20: =【表4】处理过程贰!H6 -> 盈凸月 | F20: =IF(F19="", "", IF((F19+【表3】处理过程壹!$E$5/24) >= 1, "", TEXT(F19+【表3】处理过程壹!$E$5/24,"h:mm"))) -> 8:30 | G20: =IF(F20="", "", VLOOKUP(F20,【表3】处理过程壹!$E$8:$J$55, 5, FALSE)) -> 84.200969 | H20: =IF(F20="", "", VLOOKUP(F20,【表3】处理过程壹!$E$8:$J$55, 6, FALSE)) -> 39.074865 | I20: =IF(F20="", "", G20/30) -> 2.806699
F21: =IF(F20="", "", IF((F20+【表3】处理过程壹!$E$5/24) >= 1, "", TEXT(F20+【表3】处理过程壹!$E$5/24,"h:mm"))) -> 9:00 | G21: =IF(F21="", "", VLOOKUP(F21,【表3】处理过程壹!$E$8:$J$55, 5, FALSE)) -> 87.540657 | H21: =IF(F21="", "", VLOOKUP(F21,【表3】处理过程壹!$E$8:$J$55, 6, FALSE)) -> 45.545574 | I21: =IF(F21="", "", G21/30) -> 2.9180219
A22: 计算单时刻太阳位置 | F22: =IF(F21="", "", IF((F21+【表3】处理过程壹!$E$5/24) >= 1, "", TEXT(F21+【表3】处理过程壹!$E$5/24,"h:mm"))) -> 9:30 | G22: =IF(F22="", "", VLOOKUP(F22,【表3】处理过程壹!$E$8:$J$55, 5, FALSE)) -> 91.226213 | H22: =IF(F22="", "", VLOOKUP(F22,【表3】处理过程壹!$E$8:$J$55, 6, FALSE)) -> 52.03267 | I22: =IF(F22="", "", G22/30) -> 3.0408738
F23: =IF(F22="", "", IF((F22+【表3】处理过程壹!$E$5/24) >= 1, "", TEXT(F22+【表3】处理过程壹!$E$5/24,"h:mm"))) -> 10:00 | G23: =IF(F23="", "", VLOOKUP(F23,【表3】处理过程壹!$E$8:$J$55, 5, FALSE)) -> 95.544844 | H23: =IF(F23="", "", VLOOKUP(F23,【表3】处理过程壹!$E$8:$J$55, 6, FALSE)) -> 58.508916 | I23: =IF(F23="", "", G23/30) -> 3.1848281
A24: 标准时间 | B24: 太阳方位 | C24: 太阳高度 | D24: 点钟方向 | F24: =IF(F23="", "", IF((F23+【表3】处理过程壹!$E$5/24) >= 1, "", TEXT(F23+【表3】处理过程壹!$E$5/24,"h:mm"))) -> 10:30 | G24: =IF(F24="", "", VLOOKUP(F24,【表3】处理过程壹!$E$8:$J$55, 5, FALSE)) -> 101.05253 | H24: =IF(F24="", "", VLOOKUP(F24,【表3】处理过程壹!$E$8:$J$55, 6, FALSE)) -> 64.929339 | I24: =IF(F24="", "", G24/30) -> 3.3684175
A25: 0.4 | B25: =【表3】处理过程壹!I56 -> 92.026833 | C25: =【表3】处理过程壹!J56 -> 53.329865 | D25: =B25/30 -> 3.0675611 | F25: =IF(F24="", "", IF((F24+【表3】处理过程壹!$E$5/24) >= 1, "", TEXT(F24+【表3】处理过程壹!$E$5/24,"h:mm"))) -> 11:00 | G25: =IF(F25="", "", VLOOKUP(F25,【表3】处理过程壹!$E$8:$J$55, 5, FALSE)) -> 108.99975 | H25: =IF(F25="", "", VLOOKUP(F25,【表3】处理过程壹!$E$8:$J$55, 6, FALSE)) -> 71.199603 | I25: =IF(F25="", "", G25/30) -> 3.6333249
A26: 注：仅需填写标准时间，其它会自动计算 | F26: =IF(F25="", "", IF((F25+【表3】处理过程壹!$E$5/24) >= 1, "", TEXT(F25+【表3】处理过程壹!$E$5/24,"h:mm"))) -> 11:30 | G26: =IF(F26="", "", VLOOKUP(F26,【表3】处理过程壹!$E$8:$J$55, 5, FALSE)) -> 122.74635 | H26: =IF(F26="", "", VLOOKUP(F26,【表3】处理过程壹!$E$8:$J$55, 6, FALSE)) -> 77.060155 | I26: =IF(F26="", "", G26/30) -> 4.0915451
F27: =IF(F26="", "", IF((F26+【表3】处理过程壹!$E$5/24) >= 1, "", TEXT(F26+【表3】处理过程壹!$E$5/24,"h:mm"))) -> 12:00 | G27: =IF(F27="", "", VLOOKUP(F27,【表3】处理过程壹!$E$8:$J$55, 5, FALSE)) -> 152.05362 | H27: =IF(F27="", "", VLOOKUP(F27,【表3】处理过程壹!$E$8:$J$55, 6, FALSE)) -> 81.565249 | I27: =IF(F27="", "", G27/30) -> 5.0684539
F28: =IF(F27="", "", IF((F27+【表3】处理过程壹!$E$5/24) >= 1, "", TEXT(F27+【表3】处理过程壹!$E$5/24,"h:mm"))) -> 12:30 | G28: =IF(F28="", "", VLOOKUP(F28,【表3】处理过程壹!$E$8:$J$55, 5, FALSE)) -> 201.79407 | H28: =IF(F28="", "", VLOOKUP(F28,【表3】处理过程壹!$E$8:$J$55, 6, FALSE)) -> 81.943822 | I28: =IF(F28="", "", G28/30) -> 6.726469
F29: =IF(F28="", "", IF((F28+【表3】处理过程壹!$E$5/24) >= 1, "", TEXT(F28+【表3】处理过程壹!$E$5/24,"h:mm"))) -> 13:00 | G29: =IF(F29="", "", VLOOKUP(F29,【表3】处理过程壹!$E$8:$J$55, 5, FALSE)) -> 234.46908 | H29: =IF(F29="", "", VLOOKUP(F29,【表3】处理过程壹!$E$8:$J$55, 6, FALSE)) -> 77.804433 | I29: =IF(F29="", "", G29/30) -> 7.8156361
F30: =IF(F29="", "", IF((F29+【表3】处理过程壹!$E$5/24) >= 1, "", TEXT(F29+【表3】处理过程壹!$E$5/24,"h:mm"))) -> 13:30 | G30: =IF(F30="", "", VLOOKUP(F30,【表3】处理过程壹!$E$8:$J$55, 5, FALSE)) -> 249.56604 | H30: =IF(F30="", "", VLOOKUP(F30,【表3】处理过程壹!$E$8:$J$55, 6, FALSE)) -> 72.045973 | I30: =IF(F30="", "", G30/30) -> 8.318868
F31: =IF(F30="", "", IF((F30+【表3】处理过程壹!$E$5/24) >= 1, "", TEXT(F30+【表3】处理过程壹!$E$5/24,"h:mm"))) -> 14:00 | G31: =IF(F31="", "", VLOOKUP(F31,【表3】处理过程壹!$E$8:$J$55, 5, FALSE)) -> 258.03504 | H31: =IF(F31="", "", VLOOKUP(F31,【表3】处理过程壹!$E$8:$J$55, 6, FALSE)) -> 65.81032 | I31: =IF(F31="", "", G31/30) -> 8.6011681
F32: =IF(F31="", "", IF((F31+【表3】处理过程壹!$E$5/24) >= 1, "", TEXT(F31+【表3】处理过程壹!$E$5/24,"h:mm"))) -> 14:30 | G32: =IF(F32="", "", VLOOKUP(F32,【表3】处理过程壹!$E$8:$J$55, 5, FALSE)) -> 263.78091 | H32: =IF(F32="", "", VLOOKUP(F32,【表3】处理过程壹!$E$8:$J$55, 6, FALSE)) -> 59.403235 | I32: =IF(F32="", "", G32/30) -> 8.7926969
F33: =IF(F32="", "", IF((F32+【表3】处理过程壹!$E$5/24) >= 1, "", TEXT(F32+【表3】处理过程壹!$E$5/24,"h:mm"))) -> 15:00 | G33: =IF(F33="", "", VLOOKUP(F33,【表3】处理过程壹!$E$8:$J$55, 5, FALSE)) -> 268.22192 | H33: =IF(F33="", "", VLOOKUP(F33,【表3】处理过程壹!$E$8:$J$55, 6, FALSE)) -> 52.931412 | I33: =IF(F33="", "", G33/30) -> 8.9407306
F34: =IF(F33="", "", IF((F33+【表3】处理过程壹!$E$5/24) >= 1, "", TEXT(F33+【表3】处理过程壹!$E$5/24,"h:mm"))) -> 15:30 | G34: =IF(F34="", "", VLOOKUP(F34,【表3】处理过程壹!$E$8:$J$55, 5, FALSE)) -> 271.97417 | H34: =IF(F34="", "", VLOOKUP(F34,【表3】处理过程壹!$E$8:$J$55, 6, FALSE)) -> 46.443953 | I34: =IF(F34="", "", G34/30) -> 9.0658058
F35: =IF(F34="", "", IF((F34+【表3】处理过程壹!$E$5/24) >= 1, "", TEXT(F34+【表3】处理过程壹!$E$5/24,"h:mm"))) -> 16:00 | G35: =IF(F35="", "", VLOOKUP(F35,【表3】处理过程壹!$E$8:$J$55, 5, FALSE)) -> 275.34991 | H35: =IF(F35="", "", VLOOKUP(F35,【表3】处理过程壹!$E$8:$J$55, 6, FALSE)) -> 39.969665 | I35: =IF(F35="", "", G35/30) -> 9.1783302
F36: =IF(F35="", "", IF((F35+【表3】处理过程壹!$E$5/24) >= 1, "", TEXT(F35+【表3】处理过程壹!$E$5/24,"h:mm"))) -> 16:30 | G36: =IF(F36="", "", VLOOKUP(F36,【表3】处理过程壹!$E$8:$J$55, 5, FALSE)) -> 278.52932 | H36: =IF(F36="", "", VLOOKUP(F36,【表3】处理过程壹!$E$8:$J$55, 6, FALSE)) -> 33.529538 | I36: =IF(F36="", "", G36/30) -> 9.2843108
F37: =IF(F36="", "", IF((F36+【表3】处理过程壹!$E$5/24) >= 1, "", TEXT(F36+【表3】处理过程壹!$E$5/24,"h:mm"))) -> 17:00 | G37: =IF(F37="", "", VLOOKUP(F37,【表3】处理过程壹!$E$8:$J$55, 5, FALSE)) -> 281.62954 | H37: =IF(F37="", "", VLOOKUP(F37,【表3】处理过程壹!$E$8:$J$55, 6, FALSE)) -> 27.14188 | I37: =IF(F37="", "", G37/30) -> 9.3876514
F38: =IF(F37="", "", IF((F37+【表3】处理过程壹!$E$5/24) >= 1, "", TEXT(F37+【表3】处理过程壹!$E$5/24,"h:mm"))) -> 17:30 | G38: =IF(F38="", "", VLOOKUP(F38,【表3】处理过程壹!$E$8:$J$55, 5, FALSE)) -> 284.73598 | H38: =IF(F38="", "", VLOOKUP(F38,【表3】处理过程壹!$E$8:$J$55, 6, FALSE)) -> 20.824916 | I38: =IF(F38="", "", G38/30) -> 9.4911993
... F50: =IF(F49="", "", IF((F49+【表3】处理过程壹!$E$5/24) >= 1, "", TEXT(F49+【表3】处理过程壹!$E$5/24,"h:mm"))) -> 23:30 | G50: =IF(F50="", "", VLOOKUP(F50,【表3】处理过程壹!$E$8:$J$55, 5, FALSE)) -> 346.51722 | H50: =IF(F50="", "", VLOOKUP(F50,【表3】处理过程壹!$E$8:$J$55, 6, FALSE)) -> -36.118964 | I50: =IF(F50="", "", G50/30) -> 11.550574

Sheet 【表3】处理过程壹
A1: 【处理过程，此表勿修改】 | I1: 知乎/焚躯以火；公众号/云开天明
I2: 【表3】处理过程壹：太阳角度计算
A3: 标准时区时间 | D3: 中央经度 | E3: =VLOOKUP(【表2】太阳位置计算器!$C$3,A5:B28,2,FALSE) -> 120 | F3: 日期 | G3: =【表2】太阳位置计算器!C9 -> 45846 | H3: 该年第几天 | I3: =G3-DATE(YEAR(G3),1,0) -> 189 | J3: 日角(rad) | K3: =2*PI()*($I$3-1)/365 -> 3.2362708 | L3: ET参数B | M3: =2*PI()*($I$3-81)/365 -> 1.8591343
A4: 时区 | B4: 中央经度 | D4: 时间基准 | E4: =VLOOKUP(【表2】太阳位置计算器!$C$4,A31:B32,2,FALSE) -> 1 | F4: 经度 | G4: =【表2】太阳位置计算器!C10 -> 116.9 | H4: 地理时差(h) | I4: =(G4-E3)/15 -> -0.20666667 | J4: 日赤纬角(rad) | K4: =0.006918-0.399912*COS($K$3)+0.070257*SIN($K$3)-0.006758*COS(2*$K$3)+0.000907*SIN(2*$K$3)-0.002697*COS(3*$K$3)+0.00148*SIN(3*$K$3) -> 0.39410479 | L4: 均时差ET(min) | M4: =9.87*SIN(2*M3)-7.53*COS(M3)-1.5*SIN(M3) -> -4.6783752
A5: UTC+12 | B5: 180 | D5: 时间间隔 | E5: =VLOOKUP(【表2】太阳位置计算器!$C$5,A35:B37,2,FALSE) -> 0.5 | F5: 纬度 | G5: =【表2】太阳位置计算器!C11 -> 30.1 | H5: 纬度(rad) | I5: =RADIANS(G5) -> 0.5253441 | J5: 日赤纬角(度) | K5: =DEGREES(K4) -> 22.580541
A6: UTC+11 | B6: 165
A7: UTC+10 | B7: 150 | D7: 标准时间 (平) | E7: 标准时 间转换 | F7: 当地 平太阳时 | G7: 当地 真太阳时 | H7: 时角 变化量 | I7: 太阳 方位角 | J7: 太阳 高度角 | M7: 当地真 太阳时 | N7: 标准真 太阳时 | O7: 标准平 太阳时 | P7: 根据时间基准 转换格式 | Q7: 方位或 高度
A8: UTC+9 | B8: 135 | D8: 0 | E8: =TEXT(D8/24,"h:mm") -> 0:00 | F8: =D8+$I$4 -> -0.20666667 | G8: =D8+$I$4+$M$4/60 -> -0.28463959 | H8: =IF($E$4=1,RADIANS(15*G8),RADIANS(15*F8)) -> -0.074518469 | I8: =MOD(DEGREES(ATAN2(COS($K$4)*COS(H8)*SIN($I$5)+SIN($K$4)*COS($I$5),COS($K$4)*SIN(H8))),360) -> 355.05172 | J8: =DEGREES(ASIN(SIN($K$4)*SIN($I$5)-COS($K$4)*COS(H8)*COS($I$5))) -> -37.159908 | L8: 日出 | M8: =DEGREES(ACOS(TAN(K4)*TAN(I5)))/15 -> 5.070034 | N8: =M8-$I$4 -> 5.2767006 | O8: =N8-$M$4/60 -> 5.3546736 | P8: =IF($E$4=1, TEXT(O8/24, "h:mm:ss"), TEXT(N8/24, "h:mm:ss")) -> 5:21:17 | Q8: =DEGREES(ACOS(SIN($K$4)/COS($I$5))) -> 63.651375
A9: UTC+8(北京时间) | B9: 120 | D9: 0.5 | E9: =TEXT(D9/24,"h:mm") -> 0:30 | F9: =D9+$I$4 -> 0.29333333 | G9: =D9+$I$4+$M$4/60 -> 0.21536041 | H9: =IF($E$4=1,RADIANS(15*G9),RADIANS(15*F9)) -> 0.056381224 | I9: =MOD(DEGREES(ATAN2(COS($K$4)*COS(H9)*SIN($I$5)+SIN($K$4)*COS($I$5),COS($K$4)*SIN(H9))),360) -> 3.7467785 | J9: =DEGREES(ASIN(SIN($K$4)*SIN($I$5)-COS($K$4)*COS(H9)*COS($I$5))) -> -37.228064 | L9: 日中 | M9: 12 | N9: =M9-$I$4 -> 12.206667 | O9: =N9-$M$4/60 -> 12.28464 | P9: =IF($E$4=1, TEXT(O9/24, "h:mm:ss"), TEXT(N9/24, "h:mm:ss")) -> 12:17:05 | Q9: =90-G5+K5 -> 82.480541
A10: UTC+7 | B10: 105 | D10: 1 | E10: =TEXT(D10/24,"h:mm") -> 1:00 | F10: =D10+$I$4 -> 0.79333333 | G10: =D10+$I$4+$M$4/60 -> 0.71536041 | H10: =IF($E$4=1,RADIANS(15*G10),RADIANS(15*F10)) -> 0.18728092 | I10: =MOD(DEGREES(ATAN2(COS($K$4)*COS(H10)*SIN($I$5)+SIN($K$4)*COS($I$5),COS($K$4)*SIN(H10))),360) -> 12.319737 | J10: =DEGREES(ASIN(SIN($K$4)*SIN($I$5)-COS($K$4)*COS(H10)*COS($I$5))) -> -36.319703 | L10: 日落 | M10: =24-M8 -> 18.929966 | N10: =M10-$I$4 -> 19.136633 | O10: =N10-$M$4/60 -> 19.214606 | P10: =IF($E$4=1, TEXT(O10/24, "h:mm:ss"), TEXT(N10/24, "h:mm:ss")) -> 19:12:53 | Q10: =360-Q8 -> 296.34863
A11: UTC+6 | B11: 90 | D11: 1.5 | E11: =TEXT(D11/24,"h:mm") -> 1:30 | F11: =D11+$I$4 -> 1.2933333 | G11: =D11+$I$4+$M$4/60 -> 1.2153604 | H11: =IF($E$4=1,RADIANS(15*G11),RADIANS(15*F11)) -> 0.31818061 | I11: =MOD(DEGREES(ATAN2(COS($K$4)*COS(H11)*SIN($I$5)+SIN($K$4)*COS($I$5),COS($K$4)*SIN(H11))),360) -> 20.513595 | J11: =DEGREES(ASIN(SIN($K$4)*SIN($I$5)-COS($K$4)*COS(H11)*COS($I$5))) -> -34.483036 | L11: 昼长 | M11: =M10-M8 -> 13.859932 | P11: =TEXT(M11/24, "h时mm分") -> 13时51分
A12: UTC+5 | B12: 75 | D12: 2 | E12: =TEXT(D12/24,"h:mm") -> 2:00 | F12: =D12+$I$4 -> 1.7933333 | G12: =D12+$I$4+$M$4/60 -> 1.7153604 | H12: =IF($E$4=1,RADIANS(15*G12),RADIANS(15*F12)) -> 0.44908031 | I12: =MOD(DEGREES(ATAN2(COS($K$4)*COS(H12)*SIN($I$5)+SIN($K$4)*COS($I$5),COS($K$4)*SIN(H12))),360) -> 28.143963 | J12: =DEGREES(ASIN(SIN($K$4)*SIN($I$5)-COS($K$4)*COS(H12)*COS($I$5))) -> -31.806485
A13: UTC+4 | B13: 60 | D13: 2.5 | E13: =TEXT(D13/24,"h:mm") -> 2:30 | F13: =D13+$I$4 -> 2.2933333 | G13: =D13+$I$4+$M$4/60 -> 2.2153604 | H13: =IF($E$4=1,RADIANS(15*G13),RADIANS(15*F13)) -> 0.57998 | I13: =MOD(DEGREES(ATAN2(COS($K$4)*COS(H13)*SIN($I$5)+SIN($K$4)*COS($I$5),COS($K$4)*SIN(H13))),360) -> 35.115624 | J13: =DEGREES(ASIN(SIN($K$4)*SIN($I$5)-COS($K$4)*COS(H13)*COS($I$5))) -> -28.4003
A14: UTC+3 | B14: 45 | D14: 3 | E14: =TEXT(D14/24,"h:mm") -> 3:00 | F14: =D14+$I$4 -> 2.7933333 | G14: =D14+$I$4+$M$4/60 -> 2.7153604 | H14: =IF($E$4=1,RADIANS(15*G14),RADIANS(15*F14)) -> 0.71087969 | I14: =MOD(DEGREES(ATAN2(COS($K$4)*COS(H14)*SIN($I$5)+SIN($K$4)*COS($I$5),COS($K$4)*SIN(H14))),360) -> 41.41132 | J14: =DEGREES(ASIN(SIN($K$4)*SIN($I$5)-COS($K$4)*COS(H14)*COS($I$5))) -> -24.379123
A15: UTC+2 | B15: 30 | D15: 3.5 | E15: =TEXT(D15/24,"h:mm") -> 3:30 | F15: =D15+$I$4 -> 3.2933333 | G15: =D15+$I$4+$M$4/60 -> 3.2153604 | H15: =IF($E$4=1,RADIANS(15*G15),RADIANS(15*F15)) -> 0.84177939 | I15: =MOD(DEGREES(ATAN2(COS($K$4)*COS(H15)*SIN($I$5)+SIN($K$4)*COS($I$5),COS($K$4)*SIN(H15))),360) -> 47.067443 | J15: =DEGREES(ASIN(SIN($K$4)*SIN($I$5)-COS($K$4)*COS(H15)*COS($I$5))) -> -19.849991
A16: UTC+1 | B16: 15 | D16: 4 | E16: =TEXT(D16/24,"h:mm") -> 4:00 | F16: =D16+$I$4 -> 3.7933333 | G16: =D16+$I$4+$M$4/60 -> 3.7153604 | H16: =IF($E$4=1,RADIANS(15*G16),RADIANS(15*F16)) -> 0.97267908 | I16: =MOD(DEGREES(ATAN2(COS($K$4)*COS(H16)*SIN($I$5)+SIN($K$4)*COS($I$5),COS($K$4)*SIN(H16))),360) -> 52.149901 | J16: =DEGREES(ASIN(SIN($K$4)*SIN($I$5)-COS($K$4)*COS(H16)*COS($I$5))) -> -14.906356
A17: UTC+0 | B17: 0 | D17: 4.5 | E17: =TEXT(D17/24,"h:mm") -> 4:30 | F17: =D17+$I$4 -> 4.2933333 | G17: =D17+$I$4+$M$4/60 -> 4.2153604 | H17: =IF($E$4=1,RADIANS(15*G17),RADIANS(15*F17)) -> 1.1035788 | I17: =MOD(DEGREES(ATAN2(COS($K$4)*COS(H17)*SIN($I$5)+SIN($K$4)*COS($I$5),COS($K$4)*SIN(H17))),360) -> 56.73637 | J17: =DEGREES(ASIN(SIN($K$4)*SIN($I$5)-COS($K$4)*COS(H17)*COS($I$5))) -> -9.6265057
A18: UTC-1 | B18: -15 | D18: 5 | E18: =TEXT(D18/24,"h:mm") -> 5:00 | F18: =D18+$I$4 -> 4.7933333 | G18: =D18+$I$4+$M$4/60 -> 4.7153604 | H18: =IF($E$4=1,RADIANS(15*G18),RADIANS(15*F18)) -> 1.2344785 | I18: =MOD(DEGREES(ATAN2(COS($K$4)*COS(H18)*SIN($I$5)+SIN($K$4)*COS($I$5),COS($K$4)*SIN(H18))),360) -> 60.905655 | J18: =DEGREES(ASIN(SIN($K$4)*SIN($I$5)-COS($K$4)*COS(H18)*COS($I$5))) -> -4.0745008
A19: UTC-2 | B19: -30 | D19: 5.5 | E19: =TEXT(D19/24,"h:mm") -> 5:30 | F19: =D19+$I$4 -> 5.2933333 | G19: =D19+$I$4+$M$4/60 -> 5.2153604 | H19: =IF($E$4=1,RADIANS(15*G19),RADIANS(15*F19)) -> 1.3653782 | I19: =MOD(DEGREES(ATAN2(COS($K$4)*COS(H19)*SIN($I$5)+SIN($K$4)*COS($I$5),COS($K$4)*SIN(H19))),360) -> 64.732548 | J19: =DEGREES(ASIN(SIN($K$4)*SIN($I$5)-COS($K$4)*COS(H19)*COS($I$5))) -> 1.6978359
A20: UTC-3 | B20: -45 | D20: 6 | E20: =TEXT(D20/24,"h:mm") -> 6:00 | F20: =D20+$I$4 -> 5.7933333 | G20: =D20+$I$4+$M$4/60 -> 5.7153604 | H20: =IF($E$4=1,RADIANS(15*G20),RADIANS(15*F20)) -> 1.4962779 | I20: =MOD(DEGREES(ATAN2(COS($K$4)*COS(H20)*SIN($I$5)+SIN($K$4)*COS($I$5),COS($K$4)*SIN(H20))),360) -> 68.286292 | J20: =DEGREES(ASIN(SIN($K$4)*SIN($I$5)-COS($K$4)*COS(H20)*COS($I$5))) -> 7.6486797
A21: UTC-4 | B21: -60 | D21: 6.5 | E21: =TEXT(D21/24,"h:mm") -> 6:30 | F21: =D21+$I$4 -> 6.2933333 | G21: =D21+$I$4+$M$4/60 -> 6.2153604 | H21: =IF($E$4=1,RADIANS(15*G21),RADIANS(15*F21)) -> 1.6271776 | I21: =MOD(DEGREES(ATAN2(COS($K$4)*COS(H21)*SIN($I$5)+SIN($K$4)*COS($I$5),COS($K$4)*SIN(H21))),360) -> 71.631258 | J21: =DEGREES(ASIN(SIN($K$4)*SIN($I$5)-COS($K$4)*COS(H21)*COS($I$5))) -> 13.744114
A22: UTC-5 | B22: -75 | D22: 7 | E22: =TEXT(D22/24,"h:mm") -> 7:00 | F22: =D22+$I$4 -> 6.7933333 | G22: =D22+$I$4+$M$4/60 -> 6.7153604 | H22: =IF($E$4=1,RADIANS(15*G22),RADIANS(15*F22)) -> 1.7580772 | I22: =MOD(DEGREES(ATAN2(COS($K$4)*COS(H22)*SIN($I$5)+SIN($K$4)*COS($I$5),COS($K$4)*SIN(H22))),360) -> 74.82908 | J22: =DEGREES(ASIN(SIN($K$4)*SIN($I$5)-COS($K$4)*COS(H22)*COS($I$5))) -> 19.956309
A23: UTC-6 | B23: -90 | D23: 7.5 | E23: =TEXT(D23/24,"h:mm") -> 7:30 | F23: =D23+$I$4 -> 7.2933333 | G23: =D23+$I$4+$M$4/60 -> 7.2153604 | H23: =IF($E$4=1,RADIANS(15*G23),RADIANS(15*F23)) -> 1.8889769 | I23: =MOD(DEGREES(ATAN2(COS($K$4)*COS(H23)*SIN($I$5)+SIN($K$4)*COS($I$5),COS($K$4)*SIN(H23))),360) -> 77.942098 | J23: =DEGREES(ASIN(SIN($K$4)*SIN($I$5)-COS($K$4)*COS(H23)*COS($I$5))) -> 26.261967
... A28: UTC-11 | B28: -165 | D28: 10 | E28: =TEXT(D28/24,"h:mm") -> 10:00 | F28: =D28+$I$4 -> 9.7933333 | G28: =D28+$I$4+$M$4/60 -> 9.7153604 | H28: =IF($E$4=1,RADIANS(15*G28),RADIANS(15*F28)) -> 2.5434754 | I28: =MOD(DEGREES(ATAN2(COS($K$4)*COS(H28)*SIN($I$5)+SIN($K$4)*COS($I$5),COS($K$4)*SIN(H28))),360) -> 95.544844 | J28: =DEGREES(ASIN(SIN($K$4)*SIN($I$5)-COS($K$4)*COS(H28)*COS($I$5))) -> 58.508916
D29: 10.5 | E29: =TEXT(D29/24,"h:mm") -> 10:30 | F29: =D29+$I$4 -> 10.293333 | G29: =D29+$I$4+$M$4/60 -> 10.21536 | H29: =IF($E$4=1,RADIANS(15*G29),RADIANS(15*F29)) -> 2.6743751 | I29: =MOD(DEGREES(ATAN2(COS($K$4)*COS(H29)*SIN($I$5)+SIN($K$4)*COS($I$5),COS($K$4)*SIN(H29))),360) -> 101.05253 | J29: =DEGREES(ASIN(SIN($K$4)*SIN($I$5)-COS($K$4)*COS(H29)*COS($I$5))) -> 64.929339
A30: 时间基准 | D30: 11 | E30: =TEXT(D30/24,"h:mm") -> 11:00 | F30: =D30+$I$4 -> 10.793333 | G30: =D30+$I$4+$M$4/60 -> 10.71536 | H30: =IF($E$4=1,RADIANS(15*G30),RADIANS(15*F30)) -> 2.8052748 | I30: =MOD(DEGREES(ATAN2(COS($K$4)*COS(H30)*SIN($I$5)+SIN($K$4)*COS($I$5),COS($K$4)*SIN(H30))),360) -> 108.99975 | J30: =DEGREES(ASIN(SIN($K$4)*SIN($I$5)-COS($K$4)*COS(H30)*COS($I$5))) -> 71.199603
A31: 平太阳时(推荐) | B31: 1 | D31: 11.5 | E31: =TEXT(D31/24,"h:mm") -> 11:30 | F31: =D31+$I$4 -> 11.293333 | G31: =D31+$I$4+$M$4/60 -> 11.21536 | H31: =IF($E$4=1,RADIANS(15*G31),RADIANS(15*F31)) -> 2.9361745 | I31: =MOD(DEGREES(ATAN2(COS($K$4)*COS(H31)*SIN($I$5)+SIN($K$4)*COS($I$5),COS($K$4)*SIN(H31))),360) -> 122.74635 | J31: =DEGREES(ASIN(SIN($K$4)*SIN($I$5)-COS($K$4)*COS(H31)*COS($I$5))) -> 77.060155
A32: 真太阳时 | B32: 0 | D32: 12 | E32: =TEXT(D32/24,"h:mm") -> 12:00 | F32: =D32+$I$4 -> 11.793333 | G32: =D32+$I$4+$M$4/60 -> 11.71536 | H32: =IF($E$4=1,RADIANS(15*G32),RADIANS(15*F32)) -> 3.0670742 | I32: =MOD(DEGREES(ATAN2(COS($K$4)*COS(H32)*SIN($I$5)+SIN($K$4)*COS($I$5),COS($K$4)*SIN(H32))),360) -> 152.05362 | J32: =DEGREES(ASIN(SIN($K$4)*SIN($I$5)-COS($K$4)*COS(H32)*COS($I$5))) -> 81.565249
D33: 12.5 | E33: =TEXT(D33/24,"h:mm") -> 12:30 | F33: =D33+$I$4 -> 12.293333 | G33: =D33+$I$4+$M$4/60 -> 12.21536 | H33: =IF($E$4=1,RADIANS(15*G33),RADIANS(15*F33)) -> 3.1979739 | I33: =MOD(DEGREES(ATAN2(COS($K$4)*COS(H33)*SIN($I$5)+SIN($K$4)*COS($I$5),COS($K$4)*SIN(H33))),360) -> 201.79407 | J33: =DEGREES(ASIN(SIN($K$4)*SIN($I$5)-COS($K$4)*COS(H33)*COS($I$5))) -> 81.943822
A34: 时间序列间隔 | D34: 13 | E34: =TEXT(D34/24,"h:mm") -> 13:00 | F34: =D34+$I$4 -> 12.793333 | G34: =D34+$I$4+$M$4/60 -> 12.71536 | H34: =IF($E$4=1,RADIANS(15*G34),RADIANS(15*F34)) -> 3.3288736 | I34: =MOD(DEGREES(ATAN2(COS($K$4)*COS(H34)*SIN($I$5)+SIN($K$4)*COS($I$5),COS($K$4)*SIN(H34))),360) -> 234.46908 | J34: =DEGREES(ASIN(SIN($K$4)*SIN($I$5)-COS($K$4)*COS(H34)*COS($I$5))) -> 77.804433
A35: 30分钟 | B35: 0.5 | D35: 13.5 | E35: =TEXT(D35/24,"h:mm") -> 13:30 | F35: =D35+$I$4 -> 13.293333 | G35: =D35+$I$4+$M$4/60 -> 13.21536 | H35: =IF($E$4=1,RADIANS(15*G35),RADIANS(15*F35)) -> 3.4597733 | I35: =MOD(DEGREES(ATAN2(COS($K$4)*COS(H35)*SIN($I$5)+SIN($K$4)*COS($I$5),COS($K$4)*SIN(H35))),360) -> 249.56604 | J35: =DEGREES(ASIN(SIN($K$4)*SIN($I$5)-COS($K$4)*COS(H35)*COS($I$5))) -> 72.045973
A36: 1小时 | B36: 1 | D36: 14 | E36: =TEXT(D36/24,"h:mm") -> 14:00 | F36: =D36+$I$4 -> 13.793333 | G36: =D36+$I$4+$M$4/60 -> 13.71536 | H36: =IF($E$4=1,RADIANS(15*G36),RADIANS(15*F36)) -> 3.590673 | I36: =MOD(DEGREES(ATAN2(COS($K$4)*COS(H36)*SIN($I$5)+SIN($K$4)*COS($I$5),COS($K$4)*SIN(H36))),360) -> 258.03504 | J36: =DEGREES(ASIN(SIN($K$4)*SIN($I$5)-COS($K$4)*COS(H36)*COS($I$5))) -> 65.81032
A37: 2小时 | B37: 2 | D37: 14.5 | E37: =TEXT(D37/24,"h:mm") -> 14:30 | F37: =D37+$I$4 -> 14.293333 | G37: =D37+$I$4+$M$4/60 -> 14.21536 | H37: =IF($E$4=1,RADIANS(15*G37),RADIANS(15*F37)) -> 3.7215727 | I37: =MOD(DEGREES(ATAN2(COS($K$4)*COS(H37)*SIN($I$5)+SIN($K$4)*COS($I$5),COS($K$4)*SIN(H37))),360) -> 263.78091 | J37: =DEGREES(ASIN(SIN($K$4)*SIN($I$5)-COS($K$4)*COS(H37)*COS($I$5))) -> 59.403235
D38: 15 | E38: =TEXT(D38/24,"h:mm") -> 15:00 | F38: =D38+$I$4 -> 14.793333 | G38: =D38+$I$4+$M$4/60 -> 14.71536 | H38: =IF($E$4=1,RADIANS(15*G38),RADIANS(15*F38)) -> 3.8524723 | I38: =MOD(DEGREES(ATAN2(COS($K$4)*COS(H38)*SIN($I$5)+SIN($K$4)*COS($I$5),COS($K$4)*SIN(H38))),360) -> 268.22192 | J38: =DEGREES(ASIN(SIN($K$4)*SIN($I$5)-COS($K$4)*COS(H38)*COS($I$5))) -> 52.931412
D39: 15.5 | E39: =TEXT(D39/24,"h:mm") -> 15:30 | F39: =D39+$I$4 -> 15.293333 | G39: =D39+$I$4+$M$4/60 -> 15.21536 | H39: =IF($E$4=1,RADIANS(15*G39),RADIANS(15*F39)) -> 3.983372 | I39: =MOD(DEGREES(ATAN2(COS($K$4)*COS(H39)*SIN($I$5)+SIN($K$4)*COS($I$5),COS($K$4)*SIN(H39))),360) -> 271.97417 | J39: =DEGREES(ASIN(SIN($K$4)*SIN($I$5)-COS($K$4)*COS(H39)*COS($I$5))) -> 46.443953
D40: 16 | E40: =TEXT(D40/24,"h:mm") -> 16:00 | F40: =D40+$I$4 -> 15.793333 | G40: =D40+$I$4+$M$4/60 -> 15.71536 | H40: =IF($E$4=1,RADIANS(15*G40),RADIANS(15*F40)) -> 4.1142717 | I40: =MOD(DEGREES(ATAN2(COS($K$4)*COS(H40)*SIN($I$5)+SIN($K$4)*COS($I$5),COS($K$4)*SIN(H40))),360) -> 275.34991 | J40: =DEGREES(ASIN(SIN($K$4)*SIN($I$5)-COS($K$4)*COS(H40)*COS($I$5))) -> 39.969665
D41: 16.5 | E41: =TEXT(D41/24,"h:mm") -> 16:30 | F41: =D41+$I$4 -> 16.293333 | G41: =D41+$I$4+$M$4/60 -> 16.21536 | H41: =IF($E$4=1,RADIANS(15*G41),RADIANS(15*F41)) -> 4.2451714 | I41: =MOD(DEGREES(ATAN2(COS($K$4)*COS(H41)*SIN($I$5)+SIN($K$4)*COS($I$5),COS($K$4)*SIN(H41))),360) -> 278.52932 | J41: =DEGREES(ASIN(SIN($K$4)*SIN($I$5)-COS($K$4)*COS(H41)*COS($I$5))) -> 33.529538
D42: 17 | E42: =TEXT(D42/24,"h:mm") -> 17:00 | F42: =D42+$I$4 -> 16.793333 | G42: =D42+$I$4+$M$4/60 -> 16.71536 | H42: =IF($E$4=1,RADIANS(15*G42),RADIANS(15*F42)) -> 4.3760711 | I42: =MOD(DEGREES(ATAN2(COS($K$4)*COS(H42)*SIN($I$5)+SIN($K$4)*COS($I$5),COS($K$4)*SIN(H42))),360) -> 281.62954 | J42: =DEGREES(ASIN(SIN($K$4)*SIN($I$5)-COS($K$4)*COS(H42)*COS($I$5))) -> 27.14188
D43: 17.5 | E43: =TEXT(D43/24,"h:mm") -> 17:30 | F43: =D43+$I$4 -> 17.293333 | G43: =D43+$I$4+$M$4/60 -> 17.21536 | H43: =IF($E$4=1,RADIANS(15*G43),RADIANS(15*F43)) -> 4.5069708 | I43: =MOD(DEGREES(ATAN2(COS($K$4)*COS(H43)*SIN($I$5)+SIN($K$4)*COS($I$5),COS($K$4)*SIN(H43))),360) -> 284.73598 | J43: =DEGREES(ASIN(SIN($K$4)*SIN($I$5)-COS($K$4)*COS(H43)*COS($I$5))) -> 20.824916
D44: 18 | E44: =TEXT(D44/24,"h:mm") -> 18:00 | F44: =D44+$I$4 -> 17.793333 | G44: =D44+$I$4+$M$4/60 -> 17.71536 | H44: =IF($E$4=1,RADIANS(15*G44),RADIANS(15*F44)) -> 4.6378705 | I44: =MOD(DEGREES(ATAN2(COS($K$4)*COS(H44)*SIN($I$5)+SIN($K$4)*COS($I$5),COS($K$4)*SIN(H44))),360) -> 287.91826 | J44: =DEGREES(ASIN(SIN($K$4)*SIN($I$5)-COS($K$4)*COS(H44)*COS($I$5))) -> 14.598466
...

Sheet 【表4】处理过程贰
A1: 【处理过程，此表勿修改】 | I1: 知乎/焚躯以火；公众号/云开天明
I2: 【表4】处理过程贰：月相计算
A3: 获取日期 | B3: =【表2】太阳位置计算器!C9 -> 45846 | C3: 年(Y) | D3: =YEAR(B3) -> 2025 | E3: 月(M) | F3: =MONTH(B3) -> 7
A4: 获取经度 | B4: =【表3】处理过程壹!$G$4 -> 116.9 | C4: 年'(Y') | D4: =IF(F3<=2, YEAR(B3)-1, YEAR(B3)) -> 2025 | E4: 月'(M') | F4: =IF(F3<=2, MONTH(B3)+12, MONTH(B3)) -> 7 | G4: 日(D) | H4: =DAY(B3) -> 8
A5: 参数A | B5: =INT(D4/100) -> 20 | C5: 参数B | D5: =2-B5+INT(B5/4) -> -13 | E5: 正午儒略日JD | F5: =INT(365.25*(D4+4716)) + INT(30.6001*(F4+1)) + H4 + D5 - 1524 -> 2460865
A6: 参考日(2000/1/6)JD | B6: 2451550.1 | C6: 朔望月长度 | D6: 29.53059 | E6: 月龄 | F6: =MOD(F5 - B4/360 - B6, D6) -> 12.439428 | G6: 月相 | H6: =VLOOKUP(F6,A9:B17,2,TRUE) -> 盈凸月
A8: 月龄和月相 | D8: 月出月落时间(估算)
A9: 0 | B9: 新月 | D9: 月出时间 | E9: =TEXT(MOD(6 + $F$6*0.813 -【表3】处理过程壹!I4, 24) / 24, "h:mm") -> 16:19
A10: 1.02 | B10: 蛾眉月 | D10: 月落时间 | E10: =TEXT(MOD(18 + $F$6*0.813 -【表3】处理过程壹!I4, 24) / 24, "h:mm") -> 4:19
A11: 6.37 | B11: 上弦月 | D11: 注：只是估算，误差可达1h+，高精度计算非常复杂，建议使用Star Walk等网站查找准确数据
A12: 8.4 | B12: 盈凸月
A13: 13.75 | B13: 满月
A14: 15.78 | B14: 亏凸月
A15: 21.13 | B15: 下弦月
A16: 23.17 | B16: 残月
A17: 28.51 | B17: 晦月
